<?xml version="1.0" ?>
<robot name="orne" xmlns:xacro="http://ros.org/wiki/xacro">
  <xacro:include filename="$(find orne_description)/urdf/robots/materials.xacro"/>
  <xacro:include filename="$(find orne_description)/urdf/robots/orne_alpha.gazebo.xacro"/>

  <link name="base_footprint"/>

  <joint name="base_joint" type="fixed">
    <parent link="base_footprint"/>
    <child link="base_link"/>
    <origin xyz="0.0 0.0 0.152" rpy="0 0 0"/>
  </joint>

  <link name="base_link">
    <visual>
      <origin xyz="0.0 0 0" rpy="0 0 0"/>
      <geometry>
        <mesh filename="package://orne_description/meshes/bases/orne_alpha_base.stl" scale="1 1 1"/>
      </geometry>
      <material name="light_black"/>
    </visual>

    <collision>
      <origin xyz="0.158 0 0" rpy="0 0 0"/>
      <geometry>
        <box size="0.70 0.40 0.02"/>
      </geometry>
    </collision>

    <inertial>
      <origin xyz="0 0 0" rpy="0 0 0"/>
      <mass value="15.0"/>
      <inertia ixx="0.001" ixy="0.0" ixz="0.0"
               iyy="0.001" iyz="0.0"
               izz="0.001" />
    </inertial>
  </link>

  <joint name="wheel_left_joint" type="continuous">
    <parent link="base_link"/>
    <child link="wheel_left_link"/>
    <origin xyz="0.0 0.23075 0.0" rpy="-1.57 0 0"/>
    <axis xyz="0 0 1"/>
  </joint>

  <link name="wheel_left_link">
    <visual>
      <origin xyz="0 0 0" rpy="0 3.14 0"/>
      <geometry>
        <mesh filename="package://orne_description/meshes/wheels/tire.stl" scale="1 1 1"/>
      </geometry>
      <material name="dark"/>
    </visual>

    <collision>
      <origin xyz="0 0 0" rpy="0 0 0"/>
      <geometry>
        <cylinder length="0.0225" radius="0.152"/>
      </geometry>
    </collision>

    <inertial>
      <origin xyz="0 0 0" />
      <mass value="0.2" />
        <inertia ixx="0.001" ixy="0.0" ixz="0.0"
                 iyy="0.001" iyz="0.0"
                 izz="0.001" />
    </inertial>

  </link>

  <joint name="wheel_right_joint" type="continuous">
    <parent link="base_link"/>
    <child link="wheel_right_link"/>
    <origin xyz="0.0 -0.23075 0.0" rpy="-1.57 0 0"/>
    <axis xyz="0 0 1"/>
  </joint>

  <link name="wheel_right_link">
    <visual>
      <origin xyz="0 0 0" rpy="0 0 0"/>
      <geometry>
        <mesh filename="package://orne_description/meshes/wheels/tire.stl" scale="1 1 1"/>
      </geometry>
      <material name="dark"/>
    </visual>

    <collision>
      <origin xyz="0 0 0" rpy="0 0 0"/>
      <geometry>
        <cylinder length="0.0225" radius="0.152"/>
      </geometry>
    </collision>

      <inertial>
        <origin xyz="0 0 0" />
        <mass value="0.2" />
        <inertia ixx="0.001" ixy="0.0" ixz="0.0"
                 iyy="0.001" iyz="0.0"
                 izz="0.001" />
      </inertial>

  </link>

  <joint name="caster_front_joint" type="fixed">
    <parent link="base_link"/>
    <child link="caster_front_link"/>
    <origin xyz="0.374295 0 0.015" rpy="-3.14 0 0"/>
  </joint>

  <link name="caster_front_link">
    <collision>
      <origin xyz="0 0.0 0.0835" rpy="0 0 0"/>
      <geometry>
        <box size="0.10 0.4 0.167"/>
      </geometry>
    </collision>

    <inertial>
      <origin xyz="0 0 0" />
      <mass value="1.0" />
      <inertia ixx="0.001" ixy="0.0" ixz="0.0"
               iyy="0.001" iyz="0.0"
               izz="0.001" />
    </inertial>
  </link>

  <joint name="imu_joint" type="fixed">
    <parent link="base_link"/>
    <child link="imu_link"/>
    <origin xyz="0 0 0" rpy="0 0 0"/>
  </joint>

  <link name="imu_link"/>

  <joint name="scan_joint" type="fixed">
    <parent link="base_link"/>
    <child link="base_scan"/>
    <origin xyz="0.374295 0 0.1225" rpy="0 0 0"/>
  </joint>

  <link name="base_scan">
     <visual>
      <origin xyz="-0.0125 0 -0.035" rpy="1.57 0 1.57"/>
      <geometry>
        <mesh filename="package://orne_description/meshes/sensors/UTM-30LX_LN.stl" scale="0.01 0.01 0.01"/>
      </geometry>
      <material name="dark"/>
    </visual>

    <inertial>
      <mass value="0.08" />
      <origin xyz="0 0 0" />
      <inertia ixx="0.001" ixy="0.0" ixz="0.0"
               iyy="0.001" iyz="0.0"
               izz="0.001" />
    </inertial>
  </link>

  <xacro:include filename="$(find velodyne_description)/urdf/VLP-16.urdf.xacro"/>
  <xacro:VLP-16 parent="base_scan" name="velodyne" topic="/velodyne_points" hz="10" samples="440">
  <origin xyz="-0.10 0 0.15" rpy="0 0 0" />
  </xacro:VLP-16>

</robot>
